Workbook

Sheet 01_Dashboard
A1: P2P / AUDIT COMMAND CENTER
A3: SOCIEDAD X, S.L. • DEMO SINTÉTICA • FY 2026 • v1.1.0
B5: PERIODO DE ANÁLISIS | D5: Todos | G5: El selector actualiza importes y volúmenes de cada mes. Las alertas son indicios, no conclusiones.
B7: PEDIDOS REGISTRADOS | G7: IMPORTE TOTAL POs | L7: FACTURAS REGISTRADAS
B8: =IF($D$5="Todos",SUM('11_Resumen_Mensual'!B6:B17),SUMIF('11_Resumen_Mensual'!$A$6:$A$17,$D$5,'11_Resumen_Mensual'!B$6:B$17)) | G8: =IF($D$5="Todos",SUM('11_Resumen_Mensual'!C6:C17),SUMIF('11_Resumen_Mensual'!$A$6:$A$17,$D$5,'11_Resumen_Mensual'!C$6:C$17)) | L8: =IF($D$5="Todos",SUM('11_Resumen_Mensual'!D6:D17),SUMIF('11_Resumen_Mensual'!$A$6:$A$17,$D$5,'11_Resumen_Mensual'!D$6:D$17))
B11: IMPORTE TOTAL FACTURAS | G11: EXCEPCIONES DETECTADAS | L11: EXCEPCIONES PRIORIDAD ALTA
B12: =IF($D$5="Todos",SUM('11_Resumen_Mensual'!E6:E17),SUMIF('11_Resumen_Mensual'!$A$6:$A$17,$D$5,'11_Resumen_Mensual'!E$6:E$17)) | G12: =IF($D$5="Todos",SUM('11_Resumen_Mensual'!F6:F17),SUMIF('11_Resumen_Mensual'!$A$6:$A$17,$D$5,'11_Resumen_Mensual'!F$6:F$17)) | L12: =IF($D$5="Todos",SUM('11_Resumen_Mensual'!G6:G17),SUMIF('11_Resumen_Mensual'!$A$6:$A$17,$D$5,'11_Resumen_Mensual'!G$6:G$17))
B15: ANÁLISIS MENSUAL | VOLUMEN OPERATIVO Y VALOR (€)
B17: Mes | C17: Nº POs | D17: Pedidos (€) | E17: Nº facturas | F17: Facturas (€) | G17: Alertas | H17: Altas
B18: ='11_Resumen_Mensual'!A6 | C18: ='11_Resumen_Mensual'!B6 | D18: ='11_Resumen_Mensual'!C6 | E18: ='11_Resumen_Mensual'!D6 | F18: ='11_Resumen_Mensual'!E6 | G18: ='11_Resumen_Mensual'!F6 | H18: ='11_Resumen_Mensual'!G6
B19: ='11_Resumen_Mensual'!A7 | C19: ='11_Resumen_Mensual'!B7 | D19: ='11_Resumen_Mensual'!C7 | E19: ='11_Resumen_Mensual'!D7 | F19: ='11_Resumen_Mensual'!E7 | G19: ='11_Resumen_Mensual'!F7 | H19: ='11_Resumen_Mensual'!G7
B20: ='11_Resumen_Mensual'!A8 | C20: ='11_Resumen_Mensual'!B8 | D20: ='11_Resumen_Mensual'!C8 | E20: ='11_Resumen_Mensual'!D8 | F20: ='11_Resumen_Mensual'!E8 | G20: ='11_Resumen_Mensual'!F8 | H20: ='11_Resumen_Mensual'!G8
B21: ='11_Resumen_Mensual'!A9 | C21: ='11_Resumen_Mensual'!B9 | D21: ='11_Resumen_Mensual'!C9 | E21: ='11_Resumen_Mensual'!D9 | F21: ='11_Resumen_Mensual'!E9 | G21: ='11_Resumen_Mensual'!F9 | H21: ='11_Resumen_Mensual'!G9
B22: ='11_Resumen_Mensual'!A10 | C22: ='11_Resumen_Mensual'!B10 | D22: ='11_Resumen_Mensual'!C10 | E22: ='11_Resumen_Mensual'!D10 | F22: ='11_Resumen_Mensual'!E10 | G22: ='11_Resumen_Mensual'!F10 | H22: ='11_Resumen_Mensual'!G10
B23: ='11_Resumen_Mensual'!A11 | C23: ='11_Resumen_Mensual'!B11 | D23: ='11_Resumen_Mensual'!C11 | E23: ='11_Resumen_Mensual'!D11 | F23: ='11_Resumen_Mensual'!E11 | G23: ='11_Resumen_Mensual'!F11 | H23: ='11_Resumen_Mensual'!G11
B24: ='11_Resumen_Mensual'!A12 | C24: ='11_Resumen_Mensual'!B12 | D24: ='11_Resumen_Mensual'!C12 | E24: ='11_Resumen_Mensual'!D12 | F24: ='11_Resumen_Mensual'!E12 | G24: ='11_Resumen_Mensual'!F12 | H24: ='11_Resumen_Mensual'!G12
B25: ='11_Resumen_Mensual'!A13 | C25: ='11_Resumen_Mensual'!B13 | D25: ='11_Resumen_Mensual'!C13 | E25: ='11_Resumen_Mensual'!D13 | F25: ='11_Resumen_Mensual'!E13 | G25: ='11_Resumen_Mensual'!F13 | H25: ='11_Resumen_Mensual'!G13
B26: ='11_Resumen_Mensual'!A14 | C26: ='11_Resumen_Mensual'!B14 | D26: ='11_Resumen_Mensual'!C14 | E26: ='11_Resumen_Mensual'!D14 | F26: ='11_Resumen_Mensual'!E14 | G26: ='11_Resumen_Mensual'!F14 | H26: ='11_Resumen_Mensual'!G14
B27: ='11_Resumen_Mensual'!A15 | C27: ='11_Resumen_Mensual'!B15 | D27: ='11_Resumen_Mensual'!C15 | E27: ='11_Resumen_Mensual'!D15 | F27: ='11_Resumen_Mensual'!E15 | G27: ='11_Resumen_Mensual'!F15 | H27: ='11_Resumen_Mensual'!G15
B28: ='11_Resumen_Mensual'!A16 | C28: ='11_Resumen_Mensual'!B16 | D28: ='11_Resumen_Mensual'!C16 | E28: ='11_Resumen_Mensual'!D16 | F28: ='11_Resumen_Mensual'!E16 | G28: ='11_Resumen_Mensual'!F16 | H28: ='11_Resumen_Mensual'!G16
B29: ='11_Resumen_Mensual'!A17 | C29: ='11_Resumen_Mensual'!B17 | D29: ='11_Resumen_Mensual'!C17 | E29: ='11_Resumen_Mensual'!D17 | F29: ='11_Resumen_Mensual'!E17 | G29: ='11_Resumen_Mensual'!F17 | H29: ='11_Resumen_Mensual'!G17
B32: LECTURA CORRECTA DEL DASHBOARD
B33: • Los totales de POs y facturas son series independientes y no representan cobertura monetaria.
B34: • Las excepciones de fecha se revisan, pero no prueban errores de corte contable.
B35: • El campo 'Pagado' procede de un export, no de confirmación bancaria ni de libro mayor.
B36: • Los números con signo negativo (abonos) se conservan en las sumas.
B37: • El historial de decisiones se registra en 05_Excepciones antes de volver a generar el fichero.

Sheet 02_Reconciliacion
A1: CONCILIACIÓN PEDIDOS ↔ FACTURAS
A3: Cruce 1:N por referencia PO en descripción; importes al total con IVA, no confundir con gasto devengado
A5: PO | B5: Fecha PO | C5: Proveedor | D5: Descripción | E5: Total PO € | F5: Nº facturas | G5: Facturado enlazado € | H5: Dif. PO - fact. € | I5: Facturado ERP € | J5: Resultado | K5: Aprobación PO | L5: Estado PO | M5: Facturas vinculadas | N5: Proyecto | O5: Estado proyecto | P5: Estado CECO | Q5: CECO identificado | R5: Fila origen
A6: O2690001 | B6: 19/07/2026 | C6: Proveedor Ficticio X 042, S.L. | D6: Asesoria operativa - operacion ficticia | E6: 27362.42 | F6: 2 | G6: 29765.03 | H6: -2402.61 | I6: 29765.03 | J6: SOBRE PEDIDO | K6: Aceptado | L6: Facturado | M6: FX26-000046, FX26-000382 | O6: NO INFORMADO | P6: NO INFORMADO | R6: 6
A7: O2690002 | B7: 17/04/2026 | C7: Proveedor Ficticio X 140, S.L. | D7: Servicios logisticos - operacion ficticia | E7: 7894.52 | F7: 0 | G7: 0 | H7: 7894.52 | I7: 0 | J7: SIN FACTURA LOCALIZADA | K7: Aceptado | L7: Pendiente | N7: XPR26-00164 | Proyecto demostracion 00164 | O7: VALIDO | P7: VALIDO | Q7: TECNOLOGIA_X214 | R7: 7
A8: O2690003 | B8: 07/09/2026 | C8: Proveedor Ficticio X 121, S.L. | D8: Servicios profesionales - operacion ficticia | E8: 9481.16 | F8: 0 | G8: 0 | H8: 9481.16 | I8: 0 | J8: SIN FACTURA LOCALIZADA | K8: Aceptado | L8: Pendiente | N8: XPR26-01546 | Proyecto demostracion 01546 | O8: VALIDO | P8: VALIDO | Q8: COMERCIAL_X080 | R8: 8
A9: O2690004 | B9: 25/03/2026 | C9: Proveedor Ficticio X 004, S.L. | D9: Produccion audiovisual - operacion ficticia | E9: 28118.25 | F9: 3 | G9: 28118.25 | H9: 0 | I9: 28118.25 | J9: CONCILIADO | K9: Aceptado | L9: Facturado | M9: FX26-001774, FX26-002004, FX26-002069 | N9: XPR26-00086 | Proyecto demostracion 00086 | O9: VALIDO | P9: VALIDO | Q9: TECNOLOGIA_X204 | R9: 9
A10: O2690005 | B10: 05/09/2026 | C10: Proveedor Ficticio X 121, S.L. | D10: Traduccion y localizacion - operacion ficticia | E10: 28298.46 | F10: 0 | G10: 0 | H10: 28298.46 | I10: 0 | J10: SIN FACTURA LOCALIZADA | K10: Aceptado | L10: Pendiente | N10: XPR26-03638 | Proyecto demostracion 03638 | O10: VALIDO | P10: VALIDO | Q10: CREATIVIDAD_X142 | R10: 10
A11: O2690006 | B11: 11/07/2026 | C11: Proveedor Ficticio X 151, S.L. | D11: Servicios profesionales - operacion ficticia | E11: 60605.65 | F11: 0 | G11: 0 | H11: 60605.65 | I11: 0 | J11: CANCELADO / SIN FACTURA | K11: Cancelado | L11: Pendiente | N11: XPR26-01049 | Proyecto demostracion 01049 | O11: VALIDO | P11: VALIDO | Q11: CREATIVIDAD_X232 | R11: 11
A12: O2690007 | B12: 10/08/2026 | C12: Proveedor Ficticio X 006, S.L. | D12: Mantenimiento informatico - operacion ficticia | E12: 20281.08 | F12: 0 | G12: 0 | H12: 20281.08 | I12: 0 | J12: SIN FACTURA LOCALIZADA | K12: Aceptado | L12: Pendiente | O12: NO INFORMADO | P12: VALIDO | Q12: PRODUCCION_X231 | R12: 12
A13: O2690008 | B13: 25/07/2026 | C13: Proveedor Ficticio X 079, S.L. | D13: Produccion audiovisual - operacion ficticia | E13: 14529.84 | F13: 0 | G13: 0 | H13: 14529.84 | I13: 0 | J13: SIN FACTURA LOCALIZADA | K13: Aceptado | L13: Pendiente | N13: XPR26-01278 | Proyecto demostracion 01278 | O13: VALIDO | P13: VALIDO | Q13: CREATIVIDAD_X252 | R13: 13
A14: O2690009 | B14: 29/07/2026 | C14: Proveedor Ficticio X 152, S.L. | D14: Traduccion y localizacion - operacion ficticia | E14: 312.25 | F14: 1 | G14: 312.25 | H14: 0 | I14: 312.25 | J14: CONCILIADO | K14: Aceptado | L14: Facturado | M14: FX26-001284 | O14: NO INFORMADO | P14: VALIDO | Q14: CONSULTORIA_X119 | R14: 14
A15: O2690010 | B15: 17/03/2026 | C15: Proveedor Ficticio X 032, S.L. | D15: Subcontratacion de proyectos - operacion ficticia | E15: 24527.05 | F15: 3 | G15: 24527.05 | H15: 0 | I15: 24527.05 | J15: CONCILIADO | K15: Pendiente | L15: Facturado | M15: FX26-000846, FX26-001068, FX26-001993 | N15: XPR26-02376 | Proyecto demostracion 02376 | O15: VALIDO | P15: VALIDO | Q15: ADMINISTRACION_X246 | R15: 15
A16: O2690011 | B16: 06/09/2026 | C16: Proveedor Ficticio X 138, S.L. | D16: Servicios profesionales - operacion ficticia | E16: 15799.79 | F16: 2 | G16: 15799.8 | H16: -0.01 | I16: 15799.8 | J16: CONCILIADO | K16: Aceptado | L16: Facturado | M16: FX26-000120, FX26-001875 | O16: NO INFORMADO | P16: VALIDO | Q16: FINANZAS_X247 | R16: 16
A17: O2690012 | B17: 24/07/2026 | C17: Proveedor Ficticio X 090, S.L. | D17: Subcontratacion de proyectos - operacion ficticia | E17: 5974.22 | F17: 0 | G17: 0 | H17: 5974.22 | I17: 0 | J17: SIN FACTURA LOCALIZADA | K17: Aceptado | L17: Pendiente | N17: XPR26-02296 | Proyecto demostracion 02296 | O17: VALIDO | P17: VALIDO | Q17: COMERCIAL_X080 | R17: 17
A18: O2690013 | B18: 23/03/2026 | C18: Proveedor Ficticio X 095, S.L. | D18: Alquiler de equipos - operacion ficticia | E18: 14145.04 | F18: 1 | G18: 14145.04 | H18: 0 | I18: 14145.04 | J18: CONCILIADO | K18: Aceptado | L18: Facturado | M18: FX26-000845 | N18: XPR26-00606 | Proyecto demostracion 00606 | O18: VALIDO | P18: VALIDO | Q18: CREATIVIDAD_X192 | R18: 18
A19: O2690014 | B19: 05/05/2026 | C19: Proveedor Ficticio X 137, S.L. | D19: Servicios logisticos - operacion ficticia | E19: 15928.27 | F19: 1 | G19: 15928.27 | H19: 0 | I19: 15928.27 | J19: CONCILIADO | K19: Aceptado | L19: Facturado | M19: FX26-000230 | N19: XPR26-01348 | Proyecto demostracion 01348 | O19: VALIDO | P19: VALIDO | Q19: CREATIVIDAD_X192 | R19: 19
A20: O2690015 | B20: 24/06/2026 | C20: Proveedor Ficticio X 123, S.L. | D20: Servicios de diseno - operacion ficticia | E20: 10439.37 | F20: 1 | G20: 10439.37 | H20: 0 | I20: 10439.37 | J20: CONCILIADO | K20: Aceptado | L20: Facturado | M20: FX26-001256 | O20: NO INFORMADO | P20: VALIDO | Q20: CREATIVIDAD_X042 | R20: 20
A21: O2690016 | B21: 13/05/2026 | C21: Proveedor Ficticio X 022, S.L. | D21: Produccion audiovisual - operacion ficticia | E21: 96552.01 | F21: 1 | G21: 96552.01 | H21: 0 | I21: 96552.01 | J21: CONCILIADO | K21: Aceptado | L21: Facturado | M21: FX26-001628 | O21: NO INFORMADO | P21: VALIDO | Q21: CONSULTORIA_X159 | R21: 21
A22: O2690017 | B22: 17/08/2026 | C22: Proveedor Ficticio X 015, S.L. | D22: Mantenimiento informatico - operacion ficticia | E22: 11369.96 | F22: 2 | G22: 5211.29 | H22: 6158.67 | I22: 5211.29 | J22: PARCIAL / DIFERENCIA | K22: Aceptado | L22: Parcialmente | M22: FX26-001147, FX26-001158 | N22: XPR26-00396 | Proyecto demostracion 00396 | O22: VALIDO | P22: VALIDO | Q22: CREATIVIDAD_X032 | R22: 22
A23: O2690018 | B23: 19/01/2026 | C23: Proveedor Ficticio X 041, S.L. | D23: Licencias de software - operacion ficticia | E23: 60641.49 | F23: 1 | G23: 24764.57 | H23: 35876.92 | I23: 24764.57 | J23: PARCIAL / DIFERENCIA | K23: Aceptado | L23: Parcialmente | M23: FX26-000255 | N23: XPR26-03653 | Proyecto demostracion 03653 | O23: VALIDO | P23: VALIDO | Q23: COMERCIAL_X040 | R23: 23
A24: O2690019 | B24: 13/07/2026 | C24: Proveedor Ficticio X 020, S.L. | D24: Traduccion y localizacion - operacion ficticia | E24: 22672.16 | F24: 0 | G24: 0 | H24: 22672.16 | I24: 0 | J24: SIN FACTURA LOCALIZADA | K24: Aceptado | L24: Pendiente | O24: NO INFORMADO | P24: VALIDO | Q24: CONSULTORIA_X009 | R24: 24
A25: O2690020 | B25: 21/01/2026 | C25: Proveedor Ficticio X 139, S.L. | D25: Equipamiento tecnologico - operacion ficticia | E25: 11211.04 | F25: 2 | G25: 11211.04 | H25: 0 | I25: 11211.04 | J25: CONCILIADO | K25: Aceptado | L25: Facturado | M25: FX26-000847, FX26-001278 | N25: XPR26-01281 | Proyecto demostracion 01281 | O25: VALIDO | P25: NO INFORMADO | R25: 25
A26: O2690021 | B26: 05/10/2026 | C26: Proveedor Ficticio X 120, S.L. | D26: Subcontratacion de proyectos - operacion ficticia | E26: 4279.15 | F26: 0 | G26: 0 | H26: 4279.15 | I26: 0 | J26: SIN FACTURA LOCALIZADA | K26: Aceptado | L26: Pendiente | O26: NO INFORMADO | P26: VALIDO | Q26: TECNOLOGIA_X154 | R26: 26
A27: O2690022 | B27: 06/09/2026 | C27: Proveedor Ficticio X 116, S.L. | D27: Equipamiento tecnologico - operacion ficticia | E27: 5646.18 | F27: 0 | G27: 0 | H27: 5646.18 | I27: 0 | J27: SIN FACTURA LOCALIZADA | K27: Aceptado | L27: Pendiente | N27: XPR26-02771 | Proyecto demostracion 02771 | O27: VALIDO | P27: VALIDO | Q27: FINANZAS_X117 | R27: 27
A28: O2690023 | B28: 10/02/2026 | C28: Proveedor Ficticio X 080, S.L. | D28: Asesoria operativa - operacion ficticia | E28: 21106.11 | F28: 2 | G28: 15849.8 | H28: 5256.31 | I28: 15849.8 | J28: PARCIAL / DIFERENCIA | K28: Aceptado | L28: Parcialmente | M28: FX26-000667, FX26-001528 | N28: XPR26-03635 | Proyecto demostracion 03635 | O28: VALIDO | P28: VALIDO | Q28: CREATIVIDAD_X112 | R28: 28
A29: O2690024 | B29: 14/01/2026 | C29: Proveedor Ficticio X 167, S.L. | D29: Servicios logisticos - operacion ficticia | E29: 10625.07 | F29: 0 | G29: 0 | H29: 10625.07 | I29: 0 | J29: CANCELADO / SIN FACTURA | K29: Cancelado | L29: Pendiente | O29: NO INFORMADO | P29: VALIDO | Q29: OPERACIONES_X013 | R29: 29
A30: O2690025 | B30: 02/01/2026 | C30: Proveedor Ficticio X 084, S.L. | D30: Campana de marketing - operacion ficticia | E30: 14902.77 | F30: 2 | G30: 14902.77 | H30: 0 | I30: 14902.77 | J30: CONCILIADO | K30: Aceptado | L30: Facturado | M30: FX26-000007, FX26-000794 | N30: XPR26-00654 | Proyecto demostracion 00654 | O30: VALIDO | P30: VALIDO | Q30: OPERACIONES_X113 | R30: 30
A31: O2690026 | B31: 02/08/2026 | C31: Proveedor Ficticio X 150, S.L. | D31: Licencias de software - operacion ficticia | E31: 19479.43 | F31: 1 | G31: 21651.03 | H31: -2171.6 | I31: 21651.03 | J31: SOBRE PEDIDO | K31: Aceptado | L31: Facturado | M31: FX26-000614 | N31: XPR26-01689 | Proyecto demostracion 01689 | O31: VALIDO | P31: VALIDO | Q31: FINANZAS_X227 | R31: 31
A32: O2690027 | B32: 20/04/2026 | C32: Proveedor Ficticio X 176, S.L. | D32: Produccion audiovisual - operacion ficticia | E32: 8591.27 | F32: 1 | G32: 8591.27 | H32: 0 | I32: 8591.27 | J32: CONCILIADO | K32: Aceptado | L32: Facturado | M32: FX26-000345 | O32: NO INFORMADO | P32: VALIDO | Q32: COMERCIAL_X140 | R32: 32
A33: O2690028 | B33: 13/07/2026 | C33: Proveedor Ficticio X 156, S.L. | D33: Servicios de diseno - operacion ficticia | E33: 21324.73 | F33: 1 | G33: 21324.73 | H33: 0 | I33: 21324.73 | J33: CONCILIADO | K33: Aceptado | L33: Facturado | M33: FX26-001196 | O33: NO INFORMADO | P33: VALIDO | Q33: FINANZAS_X037 | R33: 33
A34: O2690029 | B34: 23/07/2026 | C34: Proveedor Ficticio X 130, S.L. | D34: Subcontratacion de proyectos - operacion ficticia | E34: 25421.37 | F34: 1 | G34: 25421.37 | H34: 0 | I34: 25421.37 | J34: CONCILIADO | K34: Pendiente | L34: Facturado | M34: FX26-001136 | N34: XPR26-02650 | Proyecto demostracion 02650 | O34: VALIDO | P34: VALIDO | Q34: PRODUCCION_X231 | R34: 34
A35: O2690030 | B35: 20/06/2026 | C35: Proveedor Ficticio X 048, S.L. | D35: Licencias de software - operacion ficticia | E35: 5101.92 | F35: 1 | G35: 5101.92 | H35: 0 | I35: 5101.92 | J35: CONCILIADO | K35: Pendiente | L35: Facturado | M35: FX26-001693 | N35: XPR26-03114 | Proyecto demostracion 03114 | O35: VALIDO | P35: VALIDO | Q35: DISENO_X178 | R35: 35
A36: O2690031 | B36: 22/07/2026 | C36: Proveedor Ficticio X 097, S.L. | D36: Subcontratacion de proyectos - operacion ficticia | E36: 20874.84 | F36: 1 | G36: 20874.84 | H36: 0 | I36: 20874.84 | J36: CONCILIADO | K36: Aceptado | L36: Facturado | M36: FX26-001822 | N36: XPR26-01419 | Proyecto demostracion 01419 | O36: VALIDO | P36: VALIDO | Q36: TECNOLOGIA_X204 | R36: 36
A37: O2690032 | B37: 09/01/2026 | C37: Proveedor Ficticio X 049, S.L. | D37: Asesoria operativa - operacion ficticia | E37: 17693.82 | F37: 1 | G37: 17693.82 | H37: 0 | I37: 17693.82 | J37: CONCILIADO | K37: Pendiente | L37: Facturado | M37: FX26-000282 | N37: XPR26-03191 | Proyecto demostracion 03191 | O37: VALIDO | P37: VALIDO | Q37: CONSULTORIA_X109 | R37: 37
A38: O2690033 | B38: 22/01/2026 | C38: Proveedor Ficticio X 133, S.L. | D38: Servicios de diseno - operacion ficticia | E38: 5400.48 | F38: 1 | G38: 5400.48 | H38: 0 | I38: 5400.48 | J38: CONCILIADO | K38: Pendiente | L38: Facturado | M38: FX26-002085 | O38: NO INFORMADO | P38: VALIDO | Q38: CREATIVIDAD_X052 | R38: 38
A39: O2690034 | B39: 11/01/2026 | C39: Proveedor Ficticio X 002, S.L. | D39: Subcontratacion de proyectos - operacion ficticia | E39: 12026.82 | F39: 0 | G39: 0 | H39: 12026.82 | I39: 0 | J39: SIN FACTURA LOCALIZADA | K39: Aceptado | L39: Pendiente | O39: NO INFORMADO | P39: VALIDO | Q39: TECNOLOGIA_X134 | R39: 39
A40: O2690035 | B40: 23/09/2026 | C40: Proveedor Ficticio X 182, S.L. | D40: Material de oficina - operacion ficticia | E40: 8646.51 | F40: 1 | G40: 6073.78 | H40: 2572.73 | I40: 6073.78 | J40: PARCIAL / DIFERENCIA | K40: Aceptado | L40: Parcialmente | M40: FX26-002174 | N40: XPR26-00209 | Proyecto demostracion 00209 | O40: VALIDO | P40: VALIDO | Q40: COMERCIAL_X150 | R40: 40
A41: O2690036 | B41: 09/07/2026 | C41: Proveedor Ficticio X 007, S.L. | D41: Servicios de diseno - operacion ficticia | E41: 459.6 | F41: 1 | G41: 168.33 | H41: 291.27 | I41: 168.33 | J41: PARCIAL / DIFERENCIA | K41: Pendiente | L41: Parcialmente | M41: FX26-000508 | O41: NO INFORMADO | P41: VALIDO | Q41: MARKETING_X275 | R41: 41
A42: O2690037 | B42: 03/03/2026 | C42: Proveedor Ficticio X 001, S.L. | D42: Equipamiento tecnologico - operacion ficticia | E42: 4581.64 | F42: 1 | G42: 4581.64 | H42: 0 | I42: 4581.64 | J42: CONCILIADO | K42: Aceptado | L42: Facturado | M42: FX26-001479 | N42: XPR26-00986 | Proyecto demostracion 00986 | O42: VALIDO | P42: VALIDO | Q42: CONSULTORIA_X029 | R42: 42
...

Sheet 03_Facturas
A1: UNIVERSO DE FACTURAS
A3: Todas las facturas de Compras; mantener abonos y facturas sin referencia PO; fecha contable vs emisión
A5: Factura | B5: Emisión | C5: Fecha contable | D5: Proveedor | E5: Descripción | F5: PO citada | G5: Vínculo | H5: Subtotal € | I5: IVA € | J5: Total € | K5: Pagado € | L5: Pendiente € | M5: Estado | N5: Proyecto | O5: Val. proyecto | P5: Val. CECO | Q5: Cuenta | R5: Fila origen
A6: FX26-000001 | B6: 26/02/2026 | C6: 26/02/2026 | D6: Proveedor Ficticio X 233, S.L. | E6: Subcontratacion de proyectos | servicio ficticio 0001 | G6: SIN REFERENCIA PO | H6: -12760.68 | I6: 0 | J6: -12760.68 | K6: -12760.68 | L6: 0 | M6: Pagado | N6: XPR26-03528 | Proyecto demostracion 03528 | O6: VALIDO | P6: VALIDO | Q6: Publicidad, propaganda y relaciones publicas | R6: 6
A7: FX26-000002 | B7: 11/09/2026 | C7: 11/09/2026 | D7: Proveedor Ficticio X 194, S.L. | E7: Equipamiento tecnologico | servicio ficticio 0002 | G7: SIN REFERENCIA PO | H7: 12344.41 | I7: 2592.33 | J7: 14936.74 | K7: 14936.74 | L7: 0 | M7: Pagado | O7: NO INFORMADO | P7: VALIDO | Q7: Otros servicios | R7: 7
A8: FX26-000003 | B8: 03/04/2026 | C8: 03/04/2026 | D8: Proveedor Ficticio X 033, S.L. | E8: Alquiler de equipos | servicio ficticio 0003 | G8: SIN REFERENCIA PO | H8: 7664.63 | I8: 766.46 | J8: 8431.09 | K8: 8431.09 | L8: 0 | M8: Pagado | O8: NO INFORMADO | P8: VALIDO | Q8: Subcontractors | R8: 8
A9: FX26-000004 | B9: 31/03/2026 | C9: 31/03/2026 | D9: Proveedor Ficticio X 129, S.L. | E9: Mantenimiento informatico | servicio ficticio 0004 | G9: SIN REFERENCIA PO | H9: 14042.21 | I9: 2948.86 | J9: 16991.07 | K9: 16991.07 | L9: 0 | M9: Pagado | O9: NO INFORMADO | P9: VALIDO | Q9: Arrendamientos y canones | R9: 9
A10: FX26-000005 | B10: 23/05/2026 | C10: 23/05/2026 | D10: Proveedor Ficticio X 087, S.L. | E10: O2690065 | Servicios logisticos | ejemplo ficticio | F10: O2690065 | G10: VINCULADA | H10: 16745.32 | I10: 3516.52 | J10: 20261.84 | K10: 20261.84 | L10: 0 | M10: Pagado | N10: XPR26-00178 | Proyecto demostracion 00178 | O10: VALIDO | P10: VALIDO | Q10: Equipos para procesos de informacion | R10: 10
A11: FX26-000006 | B11: 11/01/2026 | C11: 11/01/2026 | D11: Proveedor Ficticio X 111, S.L. | E11: Produccion audiovisual | servicio ficticio 0006 | G11: SIN REFERENCIA PO | H11: 10788.79 | I11: 2265.65 | J11: 13054.44 | K11: 0 | L11: 13054.44 | M11: Vencido | O11: NO INFORMADO | P11: VALIDO | Q11: Otros servicios | R11: 11
A12: FX26-000007 | B12: 02/01/2026 | C12: 02/01/2026 | D12: Proveedor Ficticio X 084, S.L. | E12: O2690025 | Campana de marketing | ejemplo ficticio | F12: O2690025 | G12: VINCULADA | H12: 3569.53 | I12: 0 | J12: 3569.53 | K12: 3569.53 | L12: 0 | M12: Pagado | N12: XPR26-00654 | Proyecto demostracion 00654 | O12: VALIDO | P12: VALIDO | Q12: Material de oficina | R12: 12
A13: FX26-000008 | B13: 13/09/2026 | C13: 13/09/2026 | D13: Proveedor Ficticio X 067, S.L. | E13: Traduccion y localizacion | servicio ficticio 0008 | G13: SIN REFERENCIA PO | H13: 1655.83 | I13: 0 | J13: 1655.83 | K13: 0 | L13: 1655.83 | M13: Pendiente | N13: XPR26-02313 | Proyecto demostracion 02313 | O13: VALIDO | P13: VALIDO | Q13: TRABAJOS REALIZADOS POR OTRAS EMPRESAS | R13: 13
A14: FX26-000009 | B14: 22/03/2026 | C14: 22/03/2026 | D14: Proveedor Ficticio X 156, S.L. | E14: Campana de marketing | servicio ficticio 0009 | G14: SIN REFERENCIA PO | H14: 8771.47 | I14: 1842.01 | J14: 10613.48 | K14: 10613.48 | L14: 0 | M14: Pagado | N14: XPR26-02771 | Proyecto demostracion 02771 | O14: VALIDO | P14: VALIDO | Q14: Material de oficina | R14: 14
A15: FX26-000010 | B15: 08/04/2026 | C15: 08/04/2026 | D15: Proveedor Ficticio X 135, S.L. | E15: Campana de marketing | servicio ficticio 0010 | G15: SIN REFERENCIA PO | H15: 790.82 | I15: 166.07 | J15: 956.89 | K15: 956.89 | L15: 0 | M15: Pagado | O15: NO INFORMADO | P15: VALIDO | Q15: Material de oficina | R15: 15
A16: FX26-000011 | B16: 30/03/2026 | C16: 30/03/2026 | D16: Proveedor Ficticio X 080, S.L. | E16: O2690047 | Traduccion y localizacion | ejemplo ficticio | F16: O2690047 | G16: VINCULADA | H16: 321.16 | I16: 67.44 | J16: 388.6 | K16: 388.6 | L16: 0 | M16: Pagado | N16: XPR26-00173 | Proyecto demostracion 00173 | O16: VALIDO | P16: VALIDO | Q16: TRABAJOS REALIZADOS POR OTRAS EMPRESAS | R16: 16
A17: FX26-000012 | B17: 03/06/2026 | C17: 03/06/2026 | D17: Proveedor Ficticio X 103, S.L. | E17: Equipamiento tecnologico | servicio ficticio 0012 | G17: SIN REFERENCIA PO | H17: 12304.53 | I17: 0 | J17: 12304.53 | K17: 0 | L17: 12304.53 | M17: Vencido | N17: XPR26-01517 | Proyecto demostracion 01517 | O17: VALIDO | P17: VALIDO | Q17: Otros servicios | R17: 17
A18: FX26-000013 | B18: 18/07/2026 | C18: 18/07/2026 | D18: Proveedor Ficticio X 148, S.L. | E18: Servicios logisticos | servicio ficticio 0013 | G18: SIN REFERENCIA PO | H18: 13489.57 | I18: 2832.81 | J18: 16322.38 | K18: 5269.63 | L18: 11052.75 | M18: Vencido | N18: XPR26-02407 | Proyecto demostracion 02407 | O18: VALIDO | P18: VALIDO | Q18: Equipos para procesos de informacion | R18: 18
A19: FX26-000014 | B19: 22/02/2026 | C19: 22/02/2026 | D19: Proveedor Ficticio X 191, S.L. | E19: Campana de marketing | servicio ficticio 0014 | G19: SIN REFERENCIA PO | H19: 8377.69 | I19: 1759.31 | J19: 10137 | K19: 10137 | L19: 0 | M19: Pagado | O19: NO INFORMADO | P19: VALIDO | Q19: Material de oficina | R19: 19
A20: FX26-000015 | B20: 27/01/2026 | C20: 27/01/2026 | D20: Proveedor Ficticio X 148, S.L. | E20: Servicios de diseno | servicio ficticio 0015 | G20: SIN REFERENCIA PO | H20: 8904.99 | I20: 1870.05 | J20: 10775.04 | K20: 10775.04 | L20: 0 | M20: Pagado | N20: XPR26-02563 | Proyecto demostracion 02563 | O20: VALIDO | P20: VALIDO | Q20: TRABAJOS REALIZADOS POR OTRAS EMPRESAS | R20: 20
A21: FX26-000016 | B21: 25/06/2026 | C21: 25/06/2026 | D21: Proveedor Ficticio X 030, S.L. | E21: Asesoria operativa | servicio ficticio 0016 | G21: SIN REFERENCIA PO | H21: 4375.16 | I21: 0 | J21: 4375.16 | K21: 0 | L21: 4375.16 | M21: Vencido | N21: XPR26-03887 | Proyecto demostracion 03887 | O21: VALIDO | P21: VALIDO | Q21: Transportes | R21: 21
A22: FX26-000017 | B22: 21/07/2026 | C22: 21/07/2026 | D22: Proveedor Ficticio X 104, S.L. | E22: O2690063 | Traduccion y localizacion | ejemplo ficticio | F22: O2690063 | G22: VINCULADA | H22: 1036.62 | I22: 217.69 | J22: 1254.31 | K22: 1254.31 | L22: 0 | M22: Pagado | N22: XPR26-01235 | Proyecto demostracion 01235 | O22: VALIDO | P22: VALIDO | Q22: TRABAJOS REALIZADOS POR OTRAS EMPRESAS | R22: 22
A23: FX26-000018 | B23: 14/01/2026 | C23: 14/01/2026 | D23: Proveedor Ficticio X 061, S.L. | E23: Material de oficina | servicio ficticio 0018 | G23: SIN REFERENCIA PO | H23: 1398.38 | I23: 293.66 | J23: 1692.04 | K23: 1692.04 | L23: 0 | M23: Pagado | N23: XPR26-03880 | Proyecto demostracion 03880 | O23: VALIDO | P23: VALIDO | Q23: Servicios profesionales independientes | R23: 23
A24: FX26-000019 | B24: 12/01/2026 | C24: 12/01/2026 | D24: Proveedor Ficticio X 200, S.L. | E24: Produccion audiovisual | servicio ficticio 0019 | G24: SIN REFERENCIA PO | H24: 10564.42 | I24: 0 | J24: 10564.42 | K24: 0 | L24: 10564.42 | M24: Vencido | O24: NO INFORMADO | P24: VALIDO | Q24: Otros servicios | R24: 24
A25: FX26-000020 | B25: 14/08/2026 | C25: 14/08/2026 | D25: Proveedor Ficticio X 193, S.L. | E25: Equipamiento tecnologico | servicio ficticio 0020 | G25: SIN REFERENCIA PO | H25: 8851.6 | I25: 1858.84 | J25: 10710.44 | K25: 0 | L25: 10710.44 | M25: Vencido | O25: NO INFORMADO | P25: VALIDO | Q25: Otros servicios | R25: 25
A26: FX26-000021 | B26: 17/07/2026 | C26: 17/07/2026 | D26: Proveedor Ficticio X 235, S.L. | E26: Equipamiento tecnologico | servicio ficticio 0021 | G26: SIN REFERENCIA PO | H26: 7306.35 | I26: 1534.33 | J26: 8840.68 | K26: 0 | L26: 8840.68 | M26: Vencido | O26: NO INFORMADO | P26: VALIDO | Q26: Otros servicios | R26: 26
A27: FX26-000022 | B27: 03/07/2026 | C27: 03/07/2026 | D27: Proveedor Ficticio X 026, S.L. | E27: Asesoria operativa | servicio ficticio 0022 | G27: SIN REFERENCIA PO | H27: 5629.55 | I27: 1182.21 | J27: 6811.76 | K27: 0 | L27: 6811.76 | M27: Vencido | N27: XPR26-01689 | Proyecto demostracion 01689 | O27: VALIDO | P27: VALIDO | Q27: Transportes | R27: 27
A28: FX26-000023 | B28: 25/07/2026 | C28: 25/07/2026 | D28: Proveedor Ficticio X 021, S.L. | E28: Material de oficina | servicio ficticio 0023 | G28: SIN REFERENCIA PO | H28: 9182.29 | I28: 1928.28 | J28: 11110.57 | K28: 11110.57 | L28: 0 | M28: Pagado | N28: XPR26-01043 | Proyecto demostracion 01043 | O28: VALIDO | P28: VALIDO | Q28: Servicios profesionales independientes | R28: 28
A29: FX26-000024 | B29: 22/05/2026 | C29: 22/05/2026 | D29: Proveedor Ficticio X 123, S.L. | E29: Mantenimiento informatico | servicio ficticio 0024 | G29: SIN REFERENCIA PO | H29: 6889.34 | I29: 1446.76 | J29: 8336.1 | K29: 0 | L29: 8336.1 | M29: Vencido | O29: NO INFORMADO | P29: VALIDO | Q29: Arrendamientos y canones | R29: 29
A30: FX26-000025 | B30: 31/08/2026 | C30: 31/08/2026 | D30: Proveedor Ficticio X 189, S.L. | E30: Mantenimiento informatico | servicio ficticio 0025 | G30: SIN REFERENCIA PO | H30: 12602.69 | I30: 2646.56 | J30: 15249.25 | K30: 15249.25 | L30: 0 | M30: Pagado | N30: XPR26-03492 | Proyecto demostracion 03492 | O30: VALIDO | P30: VALIDO | Q30: Arrendamientos y canones | R30: 30
A31: FX26-000026 | B31: 28/09/2026 | C31: 28/09/2026 | D31: Proveedor Ficticio X 139, S.L. | E31: Licencias de software | servicio ficticio 0026 | G31: SIN REFERENCIA PO | H31: 10216.13 | I31: 0 | J31: 10216.13 | K31: 10216.13 | L31: 0 | M31: Pagado | N31: XPR26-03582 | Proyecto demostracion 03582 | O31: VALIDO | P31: VALIDO | Q31: Subcontractors | R31: 31
A32: FX26-000027 | B32: 07/08/2026 | C32: 07/08/2026 | D32: Proveedor Ficticio X 036, S.L. | E32: O2690235 | Subcontratacion de proyectos | ejemplo ficticio | F32: O2690235 | G32: VINCULADA | H32: 9588.06 | I32: 0 | J32: 9588.06 | K32: 0 | L32: 9588.06 | M32: Vencido | N32: XPR26-01110 | Proyecto demostracion 01110 | O32: VALIDO | P32: VALIDO | Q32: Publicidad, propaganda y relaciones publicas | R32: 32
A33: FX26-000028 | B33: 27/07/2026 | C33: 27/07/2026 | D33: Proveedor Ficticio X 234, S.L. | E33: Asistencia tecnica | servicio ficticio 0028 | G33: SIN REFERENCIA PO | H33: 11076.17 | I33: 1107.62 | J33: 12183.79 | K33: 12183.79 | L33: 0 | M33: Pagado | O33: NO INFORMADO | P33: VALIDO | Q33: Material de oficina | R33: 33
A34: FX26-000029 | B34: 31/08/2026 | C34: 31/08/2026 | D34: Proveedor Ficticio X 226, S.L. | E34: Subcontratacion de proyectos | servicio ficticio 0029 | G34: SIN REFERENCIA PO | H34: 14153.31 | I34: 2972.2 | J34: 17125.51 | K34: 17125.51 | L34: 0 | M34: Pagado | O34: NO INFORMADO | P34: VALIDO | Q34: Publicidad, propaganda y relaciones publicas | R34: 34
A35: FX26-000030 | B35: 17/01/2026 | C35: 17/01/2026 | D35: Proveedor Ficticio X 167, S.L. | E35: Produccion de contenido | servicio ficticio 0030 | G35: SIN REFERENCIA PO | H35: 8523.51 | I35: 0 | J35: 8523.51 | K35: 8523.51 | L35: 0 | M35: Pagado | N35: XPR26-00039 | Proyecto demostracion 00039 | O35: VALIDO | P35: VALIDO | Q35: Reparaciones y conservacion | R35: 35
A36: FX26-000031 | B36: 10/01/2026 | C36: 10/01/2026 | D36: Proveedor Ficticio X 031, S.L. | E36: Material de oficina | servicio ficticio 0031 | G36: SIN REFERENCIA PO | H36: 10316.08 | I36: 2166.38 | J36: 12482.46 | K36: 12482.46 | L36: 0 | M36: Pagado | O36: NO INFORMADO | P36: VALIDO | Q36: Servicios profesionales independientes | R36: 36
A37: FX26-000032 | B37: 05/06/2026 | C37: 05/06/2026 | D37: Proveedor Ficticio X 173, S.L. | E37: Produccion de contenido | servicio ficticio 0032 | G37: SIN REFERENCIA PO | H37: 2694.98 | I37: 565.95 | J37: 3260.93 | K37: 3260.93 | L37: 0 | M37: Pagado | O37: NO INFORMADO | P37: VALIDO | Q37: Reparaciones y conservacion | R37: 37
A38: FX26-000033 | B38: 11/02/2026 | C38: 11/02/2026 | D38: Proveedor Ficticio X 034, S.L. | E38: Produccion audiovisual | servicio ficticio 0033 | G38: SIN REFERENCIA PO | H38: 11577.84 | I38: 2431.35 | J38: 14009.19 | K38: 14009.19 | L38: 0 | M38: Pagado | O38: NO INFORMADO | P38: VALIDO | Q38: Otros servicios | R38: 38
A39: FX26-000034 | B39: 19/06/2026 | C39: 19/06/2026 | D39: Proveedor Ficticio X 203, S.L. | E39: Mantenimiento informatico | servicio ficticio 0034 | G39: SIN REFERENCIA PO | H39: 33.27 | I39: 6.99 | J39: 40.26 | K39: 0 | L39: 40.26 | M39: Vencido | N39: XPR26-02580 | Proyecto demostracion 02580 | O39: VALIDO | P39: VALIDO | Q39: Arrendamientos y canones | R39: 39
A40: FX26-000035 | B40: 02/04/2026 | C40: 02/04/2026 | D40: Proveedor Ficticio X 224, S.L. | E40: Produccion audiovisual | servicio ficticio 0035 | G40: SIN REFERENCIA PO | H40: 6787.48 | I40: 0 | J40: 6787.48 | K40: 0 | L40: 6787.48 | M40: Vencido | N40: XPR26-01827 | Proyecto demostracion 01827 | O40: VALIDO | P40: VALIDO | Q40: Otros servicios | R40: 40
A41: FX26-000036 | B41: 11/05/2026 | C41: 11/05/2026 | D41: Proveedor Ficticio X 135, S.L. | E41: Asesoria operativa | servicio ficticio 0036 | G41: SIN REFERENCIA PO | H41: 10323.09 | I41: 2167.85 | J41: 12490.94 | K41: 0 | L41: 12490.94 | M41: Vencido | N41: XPR26-03887 | Proyecto demostracion 03887 | O41: VALIDO | P41: VALIDO | Q41: Transportes | R41: 41
A42: FX26-000037 | B42: 18/07/2026 | C42: 18/07/2026 | D42: Proveedor Ficticio X 259, S.L. | E42: Campana de marketing | servicio ficticio 0037 | G42: SIN REFERENCIA PO | H42: 12712.81 | I42: 2669.69 | J42: 15382.5 | K42: 7547.47 | L42: 7835.03 | M42: Vencido | O42: NO INFORMADO | P42: VALIDO | Q42: Material de oficina | R42: 42
...

Sheet 04_Pedidos
A1: UNIVERSO DE PEDIDOS
A3: Fuente completa de pedidos. La presencia de factura no sustituye evidencia de recepción ni autorización.
A5: PO | B5: Fecha | C5: Proveedor | D5: Descripción | E5: Subtotal € | F5: Total € | G5: Facturado ERP € | H5: Aprobación | I5: Estado | J5: Proyecto | K5: Val. proyecto | L5: Etiquetas | M5: Val. CECO | N5: Cuenta | O5: Nº facturas | P5: Vínculo | Q5: Fila origen
A6: O2690001 | B6: 19/07/2026 | C6: Proveedor Ficticio X 042, S.L. | D6: Asesoria operativa - operacion ficticia | E6: 22613.57 | F6: 27362.42 | G6: 29765.03 | H6: Aceptado | I6: Facturado | K6: NO INFORMADO | L6: #etiqueta_demo_sin_ceco | M6: NO INFORMADO | N6: Transportes | O6: 2 | P6: SOBRE PEDIDO | Q6: 6
A7: O2690002 | B7: 17/04/2026 | C7: Proveedor Ficticio X 140, S.L. | D7: Servicios logisticos - operacion ficticia | E7: 7894.52 | F7: 7894.52 | G7: 0 | H7: Aceptado | I7: Pendiente | J7: XPR26-00164 | Proyecto demostracion 00164 | K7: VALIDO | L7: #tecnologia_x214 #entorno_demo | M7: VALIDO | N7: Equipos para procesos de informacion | O7: 0 | P7: SIN FACTURA LOCALIZADA | Q7: 7
A8: O2690003 | B8: 07/09/2026 | C8: Proveedor Ficticio X 121, S.L. | D8: Servicios profesionales - operacion ficticia | E8: 7835.67 | F8: 9481.16 | G8: 0 | H8: Aceptado | I8: Pendiente | J8: XPR26-01546 | Proyecto demostracion 01546 | K8: VALIDO | L8: #comercial_x080 #entorno_demo | M8: VALIDO | N8: Equipos para procesos de informacion | O8: 0 | P8: SIN FACTURA LOCALIZADA | Q8: 8
A9: O2690004 | B9: 25/03/2026 | C9: Proveedor Ficticio X 004, S.L. | D9: Produccion audiovisual - operacion ficticia | E9: 23238.22 | F9: 28118.25 | G9: 28118.25 | H9: Aceptado | I9: Facturado | J9: XPR26-00086 | Proyecto demostracion 00086 | K9: VALIDO | L9: #tecnologia_x204 #entorno_demo | M9: VALIDO | N9: Otros servicios | O9: 3 | P9: CONCILIADO | Q9: 9
A10: O2690005 | B10: 05/09/2026 | C10: Proveedor Ficticio X 121, S.L. | D10: Traduccion y localizacion - operacion ficticia | E10: 23387.16 | F10: 28298.46 | G10: 0 | H10: Aceptado | I10: Pendiente | J10: XPR26-03638 | Proyecto demostracion 03638 | K10: VALIDO | L10: #creatividad_x142 #entorno_demo | M10: VALIDO | N10: TRABAJOS REALIZADOS POR OTRAS EMPRESAS | O10: 0 | P10: SIN FACTURA LOCALIZADA | Q10: 10
A11: O2690006 | B11: 11/07/2026 | C11: Proveedor Ficticio X 151, S.L. | D11: Servicios profesionales - operacion ficticia | E11: 50087.31 | F11: 60605.65 | G11: 0 | H11: Cancelado | I11: Pendiente | J11: XPR26-01049 | Proyecto demostracion 01049 | K11: VALIDO | L11: #creatividad_x232 #entorno_demo | M11: VALIDO | N11: Equipos para procesos de informacion | O11: 0 | P11: CANCELADO / SIN FACTURA | Q11: 11
A12: O2690007 | B12: 10/08/2026 | C12: Proveedor Ficticio X 006, S.L. | D12: Mantenimiento informatico - operacion ficticia | E12: 16761.22 | F12: 20281.08 | G12: 0 | H12: Aceptado | I12: Pendiente | K12: NO INFORMADO | L12: #produccion_x231 #entorno_demo | M12: VALIDO | N12: Arrendamientos y canones | O12: 0 | P12: SIN FACTURA LOCALIZADA | Q12: 12
A13: O2690008 | B13: 25/07/2026 | C13: Proveedor Ficticio X 079, S.L. | D13: Produccion audiovisual - operacion ficticia | E13: 12008.13 | F13: 14529.84 | G13: 0 | H13: Aceptado | I13: Pendiente | J13: XPR26-01278 | Proyecto demostracion 01278 | K13: VALIDO | L13: #creatividad_x252 #entorno_demo | M13: VALIDO | N13: Otros servicios | O13: 0 | P13: SIN FACTURA LOCALIZADA | Q13: 13
A14: O2690009 | B14: 29/07/2026 | C14: Proveedor Ficticio X 152, S.L. | D14: Traduccion y localizacion - operacion ficticia | E14: 312.25 | F14: 312.25 | G14: 312.25 | H14: Aceptado | I14: Facturado | K14: NO INFORMADO | L14: #consultoria_x119 #entorno_demo | M14: VALIDO | N14: TRABAJOS REALIZADOS POR OTRAS EMPRESAS | O14: 1 | P14: CONCILIADO | Q14: 14
A15: O2690010 | B15: 17/03/2026 | C15: Proveedor Ficticio X 032, S.L. | D15: Subcontratacion de proyectos - operacion ficticia | E15: 20270.29 | F15: 24527.05 | G15: 24527.05 | H15: Pendiente | I15: Facturado | J15: XPR26-02376 | Proyecto demostracion 02376 | K15: VALIDO | L15: #administracion_x246 #entorno_demo | M15: VALIDO | N15: Publicidad, propaganda y relaciones publicas | O15: 3 | P15: CONCILIADO | Q15: 15
A16: O2690011 | B16: 06/09/2026 | C16: Proveedor Ficticio X 138, S.L. | D16: Servicios profesionales - operacion ficticia | E16: 13057.68 | F16: 15799.79 | G16: 15799.8 | H16: Aceptado | I16: Facturado | K16: NO INFORMADO | L16: #finanzas_x247 #entorno_demo | M16: VALIDO | N16: Equipos para procesos de informacion | O16: 2 | P16: CONCILIADO | Q16: 16
A17: O2690012 | B17: 24/07/2026 | C17: Proveedor Ficticio X 090, S.L. | D17: Subcontratacion de proyectos - operacion ficticia | E17: 4937.37 | F17: 5974.22 | G17: 0 | H17: Aceptado | I17: Pendiente | J17: XPR26-02296 | Proyecto demostracion 02296 | K17: VALIDO | L17: #comercial_x080 #entorno_demo | M17: VALIDO | N17: Publicidad, propaganda y relaciones publicas | O17: 0 | P17: SIN FACTURA LOCALIZADA | Q17: 17
A18: O2690013 | B18: 23/03/2026 | C18: Proveedor Ficticio X 095, S.L. | D18: Alquiler de equipos - operacion ficticia | E18: 14145.04 | F18: 14145.04 | G18: 14145.04 | H18: Aceptado | I18: Facturado | J18: XPR26-00606 | Proyecto demostracion 00606 | K18: VALIDO | L18: #creatividad_x192 #entorno_demo | M18: VALIDO | N18: Subcontractors | O18: 1 | P18: CONCILIADO | Q18: 18
A19: O2690014 | B19: 05/05/2026 | C19: Proveedor Ficticio X 137, S.L. | D19: Servicios logisticos - operacion ficticia | E19: 13163.86 | F19: 15928.27 | G19: 15928.27 | H19: Aceptado | I19: Facturado | J19: XPR26-01348 | Proyecto demostracion 01348 | K19: VALIDO | L19: #creatividad_x192 #entorno_demo | M19: VALIDO | N19: Equipos para procesos de informacion | O19: 1 | P19: CONCILIADO | Q19: 19
A20: O2690015 | B20: 24/06/2026 | C20: Proveedor Ficticio X 123, S.L. | D20: Servicios de diseno - operacion ficticia | E20: 8627.58 | F20: 10439.37 | G20: 10439.37 | H20: Aceptado | I20: Facturado | K20: NO INFORMADO | L20: #creatividad_x042 #entorno_demo | M20: VALIDO | N20: TRABAJOS REALIZADOS POR OTRAS EMPRESAS | O20: 1 | P20: CONCILIADO | Q20: 20
A21: O2690016 | B21: 13/05/2026 | C21: Proveedor Ficticio X 022, S.L. | D21: Produccion audiovisual - operacion ficticia | E21: 79795.05 | F21: 96552.01 | G21: 96552.01 | H21: Aceptado | I21: Facturado | K21: NO INFORMADO | L21: #consultoria_x159 #entorno_demo | M21: VALIDO | N21: Otros servicios | O21: 1 | P21: CONCILIADO | Q21: 21
A22: O2690017 | B22: 17/08/2026 | C22: Proveedor Ficticio X 015, S.L. | D22: Mantenimiento informatico - operacion ficticia | E22: 10336.33 | F22: 11369.96 | G22: 5211.29 | H22: Aceptado | I22: Parcialmente | J22: XPR26-00396 | Proyecto demostracion 00396 | K22: VALIDO | L22: #creatividad_x032 #entorno_demo | M22: VALIDO | N22: Arrendamientos y canones | O22: 2 | P22: PARCIAL / DIFERENCIA | Q22: 22
A23: O2690018 | B23: 19/01/2026 | C23: Proveedor Ficticio X 041, S.L. | D23: Licencias de software - operacion ficticia | E23: 50116.93 | F23: 60641.49 | G23: 24764.57 | H23: Aceptado | I23: Parcialmente | J23: XPR26-03653 | Proyecto demostracion 03653 | K23: VALIDO | L23: #comercial_x040 #entorno_demo | M23: VALIDO | N23: Subcontractors | O23: 1 | P23: PARCIAL / DIFERENCIA | Q23: 23
A24: O2690019 | B24: 13/07/2026 | C24: Proveedor Ficticio X 020, S.L. | D24: Traduccion y localizacion - operacion ficticia | E24: 18737.32 | F24: 22672.16 | G24: 0 | H24: Aceptado | I24: Pendiente | K24: NO INFORMADO | L24: #consultoria_x009 #entorno_demo | M24: VALIDO | N24: TRABAJOS REALIZADOS POR OTRAS EMPRESAS | O24: 0 | P24: SIN FACTURA LOCALIZADA | Q24: 24
A25: O2690020 | B25: 21/01/2026 | C25: Proveedor Ficticio X 139, S.L. | D25: Equipamiento tecnologico - operacion ficticia | E25: 9265.32 | F25: 11211.04 | G25: 11211.04 | H25: Aceptado | I25: Facturado | J25: XPR26-01281 | Proyecto demostracion 01281 | K25: VALIDO | L25: #etiqueta_demo_sin_ceco | M25: NO INFORMADO | N25: Otros servicios | O25: 2 | P25: CONCILIADO | Q25: 25
A26: O2690021 | B26: 05/10/2026 | C26: Proveedor Ficticio X 120, S.L. | D26: Subcontratacion de proyectos - operacion ficticia | E26: 3536.49 | F26: 4279.15 | G26: 0 | H26: Aceptado | I26: Pendiente | K26: NO INFORMADO | L26: #tecnologia_x154 #entorno_demo | M26: VALIDO | N26: Publicidad, propaganda y relaciones publicas | O26: 0 | P26: SIN FACTURA LOCALIZADA | Q26: 26
A27: O2690022 | B27: 06/09/2026 | C27: Proveedor Ficticio X 116, S.L. | D27: Equipamiento tecnologico - operacion ficticia | E27: 5646.18 | F27: 5646.18 | G27: 0 | H27: Aceptado | I27: Pendiente | J27: XPR26-02771 | Proyecto demostracion 02771 | K27: VALIDO | L27: #finanzas_x117 #entorno_demo | M27: VALIDO | N27: Otros servicios | O27: 0 | P27: SIN FACTURA LOCALIZADA | Q27: 27
A28: O2690023 | B28: 10/02/2026 | C28: Proveedor Ficticio X 080, S.L. | D28: Asesoria operativa - operacion ficticia | E28: 21106.11 | F28: 21106.11 | G28: 15849.8 | H28: Aceptado | I28: Parcialmente | J28: XPR26-03635 | Proyecto demostracion 03635 | K28: VALIDO | L28: #creatividad_x112 #entorno_demo | M28: VALIDO | N28: Transportes | O28: 2 | P28: PARCIAL / DIFERENCIA | Q28: 28
A29: O2690024 | B29: 14/01/2026 | C29: Proveedor Ficticio X 167, S.L. | D29: Servicios logisticos - operacion ficticia | E29: 8781.05 | F29: 10625.07 | G29: 0 | H29: Cancelado | I29: Pendiente | K29: NO INFORMADO | L29: #operaciones_x013 #entorno_demo | M29: VALIDO | N29: Equipos para procesos de informacion | O29: 0 | P29: CANCELADO / SIN FACTURA | Q29: 29
A30: O2690025 | B30: 02/01/2026 | C30: Proveedor Ficticio X 084, S.L. | D30: Campana de marketing - operacion ficticia | E30: 14902.77 | F30: 14902.77 | G30: 14902.77 | H30: Aceptado | I30: Facturado | J30: XPR26-00654 | Proyecto demostracion 00654 | K30: VALIDO | L30: #operaciones_x113 #entorno_demo | M30: VALIDO | N30: Material de oficina | O30: 2 | P30: CONCILIADO | Q30: 30
A31: O2690026 | B31: 02/08/2026 | C31: Proveedor Ficticio X 150, S.L. | D31: Licencias de software - operacion ficticia | E31: 17708.57 | F31: 19479.43 | G31: 21651.03 | H31: Aceptado | I31: Facturado | J31: XPR26-01689 | Proyecto demostracion 01689 | K31: VALIDO | L31: #finanzas_x227 #entorno_demo | M31: VALIDO | N31: Subcontractors | O31: 1 | P31: SOBRE PEDIDO | Q31: 31
A32: O2690027 | B32: 20/04/2026 | C32: Proveedor Ficticio X 176, S.L. | D32: Produccion audiovisual - operacion ficticia | E32: 7100.22 | F32: 8591.27 | G32: 8591.27 | H32: Aceptado | I32: Facturado | K32: NO INFORMADO | L32: #comercial_x140 #entorno_demo | M32: VALIDO | N32: Otros servicios | O32: 1 | P32: CONCILIADO | Q32: 32
A33: O2690028 | B33: 13/07/2026 | C33: Proveedor Ficticio X 156, S.L. | D33: Servicios de diseno - operacion ficticia | E33: 17623.74 | F33: 21324.73 | G33: 21324.73 | H33: Aceptado | I33: Facturado | K33: NO INFORMADO | L33: #finanzas_x037 #entorno_demo | M33: VALIDO | N33: TRABAJOS REALIZADOS POR OTRAS EMPRESAS | O33: 1 | P33: CONCILIADO | Q33: 33
A34: O2690029 | B34: 23/07/2026 | C34: Proveedor Ficticio X 130, S.L. | D34: Subcontratacion de proyectos - operacion ficticia | E34: 21009.4 | F34: 25421.37 | G34: 25421.37 | H34: Pendiente | I34: Facturado | J34: XPR26-02650 | Proyecto demostracion 02650 | K34: VALIDO | L34: #produccion_x231 #entorno_demo | M34: VALIDO | N34: Publicidad, propaganda y relaciones publicas | O34: 1 | P34: CONCILIADO | Q34: 34
A35: O2690030 | B35: 20/06/2026 | C35: Proveedor Ficticio X 048, S.L. | D35: Licencias de software - operacion ficticia | E35: 5101.92 | F35: 5101.92 | G35: 5101.92 | H35: Pendiente | I35: Facturado | J35: XPR26-03114 | Proyecto demostracion 03114 | K35: VALIDO | L35: #diseno_x178 #entorno_demo | M35: VALIDO | N35: Subcontractors | O35: 1 | P35: CONCILIADO | Q35: 35
A36: O2690031 | B36: 22/07/2026 | C36: Proveedor Ficticio X 097, S.L. | D36: Subcontratacion de proyectos - operacion ficticia | E36: 17251.93 | F36: 20874.84 | G36: 20874.84 | H36: Aceptado | I36: Facturado | J36: XPR26-01419 | Proyecto demostracion 01419 | K36: VALIDO | L36: #tecnologia_x204 #entorno_demo | M36: VALIDO | N36: Publicidad, propaganda y relaciones publicas | O36: 1 | P36: CONCILIADO | Q36: 36
A37: O2690032 | B37: 09/01/2026 | C37: Proveedor Ficticio X 049, S.L. | D37: Asesoria operativa - operacion ficticia | E37: 14622.99 | F37: 17693.82 | G37: 17693.82 | H37: Pendiente | I37: Facturado | J37: XPR26-03191 | Proyecto demostracion 03191 | K37: VALIDO | L37: #consultoria_x109 #entorno_demo | M37: VALIDO | N37: Transportes | O37: 1 | P37: CONCILIADO | Q37: 37
A38: O2690033 | B38: 22/01/2026 | C38: Proveedor Ficticio X 133, S.L. | D38: Servicios de diseno - operacion ficticia | E38: 4463.21 | F38: 5400.48 | G38: 5400.48 | H38: Pendiente | I38: Facturado | K38: NO INFORMADO | L38: #creatividad_x052 #entorno_demo | M38: VALIDO | N38: TRABAJOS REALIZADOS POR OTRAS EMPRESAS | O38: 1 | P38: CONCILIADO | Q38: 38
A39: O2690034 | B39: 11/01/2026 | C39: Proveedor Ficticio X 002, S.L. | D39: Subcontratacion de proyectos - operacion ficticia | E39: 9939.52 | F39: 12026.82 | G39: 0 | H39: Aceptado | I39: Pendiente | K39: NO INFORMADO | L39: #tecnologia_x134 #entorno_demo | M39: VALIDO | N39: Publicidad, propaganda y relaciones publicas | O39: 0 | P39: SIN FACTURA LOCALIZADA | Q39: 39
A40: O2690035 | B40: 23/09/2026 | C40: Proveedor Ficticio X 182, S.L. | D40: Material de oficina - operacion ficticia | E40: 7145.88 | F40: 8646.51 | G40: 6073.78 | H40: Aceptado | I40: Parcialmente | J40: XPR26-00209 | Proyecto demostracion 00209 | K40: VALIDO | L40: #comercial_x150 #entorno_demo | M40: VALIDO | N40: Servicios profesionales independientes | O40: 1 | P40: PARCIAL / DIFERENCIA | Q40: 40
A41: O2690036 | B41: 09/07/2026 | C41: Proveedor Ficticio X 007, S.L. | D41: Servicios de diseno - operacion ficticia | E41: 459.6 | F41: 459.6 | G41: 168.33 | H41: Pendiente | I41: Parcialmente | K41: NO INFORMADO | L41: #marketing_x275 #entorno_demo | M41: VALIDO | N41: TRABAJOS REALIZADOS POR OTRAS EMPRESAS | O41: 1 | P41: PARCIAL / DIFERENCIA | Q41: 41
A42: O2690037 | B42: 03/03/2026 | C42: Proveedor Ficticio X 001, S.L. | D42: Equipamiento tecnologico - operacion ficticia | E42: 3786.48 | F42: 4581.64 | G42: 4581.64 | H42: Aceptado | I42: Facturado | J42: XPR26-00986 | Proyecto demostracion 00986 | K42: VALIDO | L42: #consultoria_x029 #entorno_demo | M42: VALIDO | N42: Otros servicios | O42: 1 | P42: CONCILIADO | Q42: 42
...

Sheet 05_Excepciones
A1: REGISTRO DE EXCEPCIONES / WORKPAPERS
A3: Cada alerta es una hipótesis de riesgo; el auditor debe documentar evidencia, criterio y resolución.
A5: ID estable | B5: Prioridad | C5: Control | D5: Origen | E5: Referencia | F5: Proveedor | G5: Motivo / evidencia pendiente | H5: Impacto indicativo € | I5: Estado revisión | J5: Responsable | K5: Conclusión / notas | L5: Fila origen
A6: EX-656C82BAF0 | B6: Alta | C6: DUP_VENDOR_INVOICE | D6: FACTURA | E6: FX26-000071 | F6: Proveedor Ficticio X 153, S.L. | G6: Se repite combinación proveedor + número de factura. | H6: 6888.78 | I6: Pendiente | L6: 76
A7: EX-73D214BCC0 | B7: Alta | C7: DUP_VENDOR_INVOICE | D7: FACTURA | E7: FX26-000071 | F7: Proveedor Ficticio X 153, S.L. | G7: Se repite combinación proveedor + número de factura. | H7: 6888.78 | I7: Pendiente | L7: 94
A8: EX-3CB494038B | B8: Alta | C8: DUP_VENDOR_INVOICE | D8: FACTURA | E8: FX26-000241 | F8: Proveedor Ficticio X 148, S.L. | G8: Se repite combinación proveedor + número de factura. | H8: 2340.21 | I8: Pendiente | L8: 263
A9: EX-604642CB29 | B9: Alta | C9: DUP_VENDOR_INVOICE | D9: FACTURA | E9: FX26-000241 | F9: Proveedor Ficticio X 148, S.L. | G9: Se repite combinación proveedor + número de factura. | H9: 2340.21 | I9: Pendiente | L9: 246
A10: EX-0B4F35DD98 | B10: Alta | C10: DUP_VENDOR_INVOICE | D10: FACTURA | E10: FX26-000322 | F10: Proveedor Ficticio X 176, S.L. | G10: Se repite combinación proveedor + número de factura. | H10: 13218.97 | I10: Pendiente | L10: 348
A11: EX-B8CD97588E | B11: Alta | C11: DUP_VENDOR_INVOICE | D11: FACTURA | E11: FX26-000322 | F11: Proveedor Ficticio X 176, S.L. | G11: Se repite combinación proveedor + número de factura. | H11: 13218.97 | I11: Pendiente | L11: 327
A12: EX-32F8DA39CE | B12: Alta | C12: DUP_VENDOR_INVOICE | D12: FACTURA | E12: FX26-000511 | F12: Proveedor Ficticio X 161, S.L. | G12: Se repite combinación proveedor + número de factura. | H12: 2773.05 | I12: Pendiente | L12: 516
A13: EX-B0E1FC0A1B | B13: Alta | C13: DUP_VENDOR_INVOICE | D13: FACTURA | E13: FX26-000511 | F13: Proveedor Ficticio X 161, S.L. | G13: Se repite combinación proveedor + número de factura. | H13: 2773.05 | I13: Pendiente | L13: 547
A14: EX-36E55AC224 | B14: Alta | C14: DUP_VENDOR_INVOICE | D14: FACTURA | E14: FX26-000802 | F14: Proveedor Ficticio X 239, S.L. | G14: Se repite combinación proveedor + número de factura. | H14: 7259.06 | I14: Pendiente | L14: 807
A15: EX-4748D56E18 | B15: Alta | C15: DUP_VENDOR_INVOICE | D15: FACTURA | E15: FX26-000802 | F15: Proveedor Ficticio X 239, S.L. | G15: Se repite combinación proveedor + número de factura. | H15: 7259.06 | I15: Pendiente | L15: 829
A16: EX-A2C0809B1C | B16: Alta | C16: DUP_VENDOR_INVOICE | D16: FACTURA | E16: FX26-001011 | F16: Proveedor Ficticio X 105, S.L. | G16: Se repite combinación proveedor + número de factura. | H16: 16036.29 | I16: Pendiente | L16: 1016
A17: EX-CEF25F026D | B17: Alta | C17: DUP_VENDOR_INVOICE | D17: FACTURA | E17: FX26-001011 | F17: Proveedor Ficticio X 105, S.L. | G17: Se repite combinación proveedor + número de factura. | H17: 16036.29 | I17: Pendiente | L17: 1026
... A253: EX-3C544F7FE1 | B253: Media | C253: PO_INVOICE_NOT_FOUND | D253: PEDIDO | E253: O2690424 | F253: Proveedor Ficticio X 084, S.L. | G253: No consta factura referenciada; valorar estado, servicio recibido y accruals. | H253: 27947.35 | I253: Pendiente | L253: 429

Sheet 06_Sin_Factura
A1: PEDIDOS SIN FACTURA VINCULADA
A3: Diferenciar 'facturado ERP sin referencia' de 'sin factura localizada' y de pedidos cancelados.
A5: PO | B5: Fecha | C5: Proveedor | D5: Total PO € | E5: Facturado ERP € | F5: Aprobación | G5: Estado | H5: Clasificación | I5: Proyecto | J5: Etiquetas | K5: Fila origen
A6: O2690002 | B6: 17/04/2026 | C6: Proveedor Ficticio X 140, S.L. | D6: 7894.52 | E6: 0 | F6: Aceptado | G6: Pendiente | H6: SIN FACTURA LOCALIZADA | I6: XPR26-00164 | Proyecto demostracion 00164 | J6: #tecnologia_x214 #entorno_demo | K6: 7
A7: O2690003 | B7: 07/09/2026 | C7: Proveedor Ficticio X 121, S.L. | D7: 9481.16 | E7: 0 | F7: Aceptado | G7: Pendiente | H7: SIN FACTURA LOCALIZADA | I7: XPR26-01546 | Proyecto demostracion 01546 | J7: #comercial_x080 #entorno_demo | K7: 8
A8: O2690005 | B8: 05/09/2026 | C8: Proveedor Ficticio X 121, S.L. | D8: 28298.46 | E8: 0 | F8: Aceptado | G8: Pendiente | H8: SIN FACTURA LOCALIZADA | I8: XPR26-03638 | Proyecto demostracion 03638 | J8: #creatividad_x142 #entorno_demo | K8: 10
A9: O2690006 | B9: 11/07/2026 | C9: Proveedor Ficticio X 151, S.L. | D9: 60605.65 | E9: 0 | F9: Cancelado | G9: Pendiente | H9: CANCELADO / SIN FACTURA | I9: XPR26-01049 | Proyecto demostracion 01049 | J9: #creatividad_x232 #entorno_demo | K9: 11
A10: O2690007 | B10: 10/08/2026 | C10: Proveedor Ficticio X 006, S.L. | D10: 20281.08 | E10: 0 | F10: Aceptado | G10: Pendiente | H10: SIN FACTURA LOCALIZADA | J10: #produccion_x231 #entorno_demo | K10: 12
A11: O2690008 | B11: 25/07/2026 | C11: Proveedor Ficticio X 079, S.L. | D11: 14529.84 | E11: 0 | F11: Aceptado | G11: Pendiente | H11: SIN FACTURA LOCALIZADA | I11: XPR26-01278 | Proyecto demostracion 01278 | J11: #creatividad_x252 #entorno_demo | K11: 13
A12: O2690012 | B12: 24/07/2026 | C12: Proveedor Ficticio X 090, S.L. | D12: 5974.22 | E12: 0 | F12: Aceptado | G12: Pendiente | H12: SIN FACTURA LOCALIZADA | I12: XPR26-02296 | Proyecto demostracion 02296 | J12: #comercial_x080 #entorno_demo | K12: 17
A13: O2690019 | B13: 13/07/2026 | C13: Proveedor Ficticio X 020, S.L. | D13: 22672.16 | E13: 0 | F13: Aceptado | G13: Pendiente | H13: SIN FACTURA LOCALIZADA | J13: #consultoria_x009 #entorno_demo | K13: 24
A14: O2690021 | B14: 05/10/2026 | C14: Proveedor Ficticio X 120, S.L. | D14: 4279.15 | E14: 0 | F14: Aceptado | G14: Pendiente | H14: SIN FACTURA LOCALIZADA | J14: #tecnologia_x154 #entorno_demo | K14: 26
A15: O2690022 | B15: 06/09/2026 | C15: Proveedor Ficticio X 116, S.L. | D15: 5646.18 | E15: 0 | F15: Aceptado | G15: Pendiente | H15: SIN FACTURA LOCALIZADA | I15: XPR26-02771 | Proyecto demostracion 02771 | J15: #finanzas_x117 #entorno_demo | K15: 27
A16: O2690024 | B16: 14/01/2026 | C16: Proveedor Ficticio X 167, S.L. | D16: 10625.07 | E16: 0 | F16: Cancelado | G16: Pendiente | H16: CANCELADO / SIN FACTURA | J16: #operaciones_x013 #entorno_demo | K16: 29
A17: O2690034 | B17: 11/01/2026 | C17: Proveedor Ficticio X 002, S.L. | D17: 12026.82 | E17: 0 | F17: Aceptado | G17: Pendiente | H17: SIN FACTURA LOCALIZADA | J17: #tecnologia_x134 #entorno_demo | K17: 39
A18: O2690038 | B18: 09/09/2026 | C18: Proveedor Ficticio X 155, S.L. | D18: 23952.65 | E18: 0 | F18: Aceptado | G18: Pendiente | H18: SIN FACTURA LOCALIZADA | I18: XPR26-00923 | Proyecto demostracion 00923 | J18: #creatividad_x062 #entorno_demo | K18: 43
A19: O2690039 | B19: 29/08/2026 | C19: Proveedor Ficticio X 075, S.L. | D19: 3408.37 | E19: 0 | F19: Pendiente | G19: Pendiente | H19: SIN FACTURA LOCALIZADA | I19: XPR26-00930 | Proyecto demostracion 00930 | J19: #etiqueta_demo_sin_ceco | K19: 44
A20: O2690040 | B20: 09/09/2026 | C20: Proveedor Ficticio X 139, S.L. | D20: 14996.4 | E20: 0 | F20: Pendiente | G20: Pendiente | H20: SIN FACTURA LOCALIZADA | I20: XPR26-00795 | Proyecto demostracion 00795 | J20: #produccion_x071 #entorno_demo | K20: 45
A21: O2690049 | B21: 21/02/2026 | C21: Proveedor Ficticio X 167, S.L. | D21: 11382.77 | E21: 0 | F21: Pendiente | G21: Pendiente | H21: SIN FACTURA LOCALIZADA | I21: XPR26-00667 | Proyecto demostracion 00667 | J21: #comercial_x080 #entorno_demo | K21: 54
A22: O2690050 | B22: 27/08/2026 | C22: Proveedor Ficticio X 146, S.L. | D22: 781.76 | E22: 0 | F22: Aceptado | G22: Pendiente | H22: SIN FACTURA LOCALIZADA | I22: XPR26-03762 | Proyecto demostracion 03762 | J22: #finanzas_x147 #entorno_demo | K22: 55
A23: O2690052 | B23: 04/03/2026 | C23: Proveedor Ficticio X 031, S.L. | D23: 24403.53 | E23: 0 | F23: Aceptado | G23: Pendiente | H23: SIN FACTURA LOCALIZADA | J23: #produccion_x091 #entorno_demo | K23: 57
A24: O2690054 | B24: 28/03/2026 | C24: Proveedor Ficticio X 012, S.L. | D24: 21437.91 | E24: 0 | F24: Aceptado | G24: Pendiente | H24: SIN FACTURA LOCALIZADA | I24: XPR26-00964 | Proyecto demostracion 00964 | J24: #diseno_x238 #entorno_demo | K24: 59
A25: O2690057 | B25: 29/07/2026 | C25: Proveedor Ficticio X 020, S.L. | D25: 797.2 | E25: 0 | F25: Aceptado | G25: Pendiente | H25: SIN FACTURA LOCALIZADA | I25: XPR26-02237 | Proyecto demostracion 02237 | J25: #finanzas_x167 #entorno_demo | K25: 62
A26: O2690059 | B26: 02/02/2026 | C26: Proveedor Ficticio X 133, S.L. | D26: 25598.93 | E26: 0 | F26: Cancelado | G26: Pendiente | H26: CANCELADO / SIN FACTURA | I26: XPR26-02407 | Proyecto demostracion 02407 | J26: #produccion_x091 #entorno_demo | K26: 64
A27: O2690061 | B27: 08/02/2026 | C27: Proveedor Ficticio X 077, S.L. | D27: 54003.11 | E27: 0 | F27: Aceptado | G27: Pendiente | H27: SIN FACTURA LOCALIZADA | J27: #consultoria_x089 #entorno_demo | K27: 66
A28: O2690066 | B28: 18/07/2026 | C28: Proveedor Ficticio X 065, S.L. | D28: 18000.09 | E28: 0 | F28: Aceptado | G28: Pendiente | H28: SIN FACTURA LOCALIZADA | J28: #operaciones_x253 #entorno_demo | K28: 71
A29: O2690069 | B29: 29/01/2026 | C29: Proveedor Ficticio X 096, S.L. | D29: 21479.63 | E29: 0 | F29: Aceptado | G29: Pendiente | H29: SIN FACTURA LOCALIZADA | J29: #marketing_x055 #entorno_demo | K29: 74
A30: O2690070 | B30: 26/06/2026 | C30: Proveedor Ficticio X 140, S.L. | D30: 16955.27 | E30: 0 | F30: Aceptado | G30: Pendiente | H30: SIN FACTURA LOCALIZADA | I30: XPR26-03729 | Proyecto demostracion 03729 | J30: #diseno_x238 #entorno_demo | K30: 75
A31: O2690072 | B31: 24/02/2026 | C31: Proveedor Ficticio X 138, S.L. | D31: 2449.52 | E31: 0 | F31: Aceptado | G31: Pendiente | H31: SIN FACTURA LOCALIZADA | I31: XPR26-01878 | Proyecto demostracion 01878 | J31: #marketing_x165 #entorno_demo | K31: 77
A32: O2690073 | B32: 06/02/2026 | C32: Proveedor Ficticio X 080, S.L. | D32: 5398.84 | E32: 0 | F32: Aceptado | G32: Pendiente | H32: SIN FACTURA LOCALIZADA | I32: XPR26-00316 | Proyecto demostracion 00316 | J32: #finanzas_x077 #entorno_demo | K32: 78
A33: O2690077 | B33: 19/07/2026 | C33: Proveedor Ficticio X 015, S.L. | D33: 22852.58 | E33: 0 | F33: Aceptado | G33: Pendiente | H33: SIN FACTURA LOCALIZADA | I33: XPR26-00923 | Proyecto demostracion 00923 | J33: #etiqueta_demo_sin_ceco | K33: 82
A34: O2690078 | B34: 01/04/2026 | C34: Proveedor Ficticio X 057, S.L. | D34: 16322.86 | E34: 0 | F34: Aceptado | G34: Pendiente | H34: SIN FACTURA LOCALIZADA | I34: XPR26-03886 | Proyecto demostracion 03886 | J34: #marketing_x205 #entorno_demo | K34: 83
A35: O2690083 | B35: 04/01/2026 | C35: Proveedor Ficticio X 022, S.L. | D35: 22668.54 | E35: 0 | F35: Aceptado | G35: Pendiente | H35: SIN FACTURA LOCALIZADA | J35: #consultoria_x169 #entorno_demo | K35: 88
A36: O2690086 | B36: 13/04/2026 | C36: Proveedor Ficticio X 036, S.L. | D36: 1594.36 | E36: 0 | F36: Aceptado | G36: Pendiente | H36: SIN FACTURA LOCALIZADA | I36: XPR26-00491 | Proyecto demostracion 00491 | J36: #consultoria_x159 #entorno_demo | K36: 91
A37: O2690095 | B37: 13/08/2026 | C37: Proveedor Ficticio X 021, S.L. | D37: 22850.1 | E37: 0 | F37: Pendiente | G37: Pendiente | H37: SIN FACTURA LOCALIZADA | J37: #marketing_x165 #entorno_demo | K37: 100
A38: O2690099 | B38: 05/04/2026 | C38: Proveedor Ficticio X 133, S.L. | D38: 6869.39 | E38: 0 | F38: Aceptado | G38: Pendiente | H38: SIN FACTURA LOCALIZADA | I38: XPR26-02124 | Proyecto demostracion 02124 | J38: #marketing_x255 #entorno_demo | K38: 104
A39: O2690103 | B39: 08/09/2026 | C39: Proveedor Ficticio X 152, S.L. | D39: 17847.78 | E39: 0 | F39: Aceptado | G39: Pendiente | H39: SIN FACTURA LOCALIZADA | J39: #produccion_x041 #entorno_demo | K39: 108
A40: O2690106 | B40: 21/03/2026 | C40: Proveedor Ficticio X 100, S.L. | D40: 10052.6 | E40: 0 | F40: Aceptado | G40: Pendiente | H40: SIN FACTURA LOCALIZADA | I40: XPR26-02650 | Proyecto demostracion 02650 | J40: #produccion_x231 #entorno_demo | K40: 111
A41: O2690114 | B41: 07/07/2026 | C41: Proveedor Ficticio X 003, S.L. | D41: 2644.04 | E41: 0 | F41: Aceptado | G41: Pendiente | H41: SIN FACTURA LOCALIZADA | I41: XPR26-03386 | Proyecto demostracion 03386 | J41: #creatividad_x142 #entorno_demo | K41: 119
A42: O2690117 | B42: 02/05/2026 | C42: Proveedor Ficticio X 179, S.L. | D42: 7777.72 | E42: 0 | F42: Pendiente | G42: Pendiente | H42: SIN FACTURA LOCALIZADA | J42: #comercial_x120 #entorno_demo | K42: 122
...

Sheet 07_Sin_PO
A1: FACTURAS SIN PO ENLAZADA
A3: No todas las compras requieren PO; aplicar política de autorizaciones antes de concluir incumplimientos.
A5: Factura | B5: Emisión | C5: Proveedor | D5: Descripción | E5: Total € | F5: Ref PO no localizada | G5: Estado | H5: Proyecto | I5: Fila origen
A6: FX26-000001 | B6: 26/02/2026 | C6: Proveedor Ficticio X 233, S.L. | D6: Subcontratacion de proyectos | servicio ficticio 0001 | E6: -12760.68 | G6: Pagado | H6: XPR26-03528 | Proyecto demostracion 03528 | I6: 6
A7: FX26-000002 | B7: 11/09/2026 | C7: Proveedor Ficticio X 194, S.L. | D7: Equipamiento tecnologico | servicio ficticio 0002 | E7: 14936.74 | G7: Pagado | I7: 7
A8: FX26-000003 | B8: 03/04/2026 | C8: Proveedor Ficticio X 033, S.L. | D8: Alquiler de equipos | servicio ficticio 0003 | E8: 8431.09 | G8: Pagado | I8: 8
A9: FX26-000004 | B9: 31/03/2026 | C9: Proveedor Ficticio X 129, S.L. | D9: Mantenimiento informatico | servicio ficticio 0004 | E9: 16991.07 | G9: Pagado | I9: 9
A10: FX26-000006 | B10: 11/01/2026 | C10: Proveedor Ficticio X 111, S.L. | D10: Produccion audiovisual | servicio ficticio 0006 | E10: 13054.44 | G10: Vencido | I10: 11
A11: FX26-000008 | B11: 13/09/2026 | C11: Proveedor Ficticio X 067, S.L. | D11: Traduccion y localizacion | servicio ficticio 0008 | E11: 1655.83 | G11: Pendiente | H11: XPR26-02313 | Proyecto demostracion 02313 | I11: 13
A12: FX26-000009 | B12: 22/03/2026 | C12: Proveedor Ficticio X 156, S.L. | D12: Campana de marketing | servicio ficticio 0009 | E12: 10613.48 | G12: Pagado | H12: XPR26-02771 | Proyecto demostracion 02771 | I12: 14
